Workbook

Sheet Cover
B2: Integrated Three-Statement Model & DCF Valuation
B3: =Inputs!$D$5&" | "&Inputs!$D$6&" | Active scenario: "&Inputs!$D$9 -> ITC Limited | INR crore (Rs cr) | Active scenario: Base
A5: # | B5: Model overview
B6: • Fully linked Income Statement, Balance Sheet and Cash Flow with a 5-year forecast (FY2026E-FY2030E) on 5 years of history.
B7: • Driver-based forecasting: growth, cost ratios, working-capital days, capex, D&A roll-forward, payout and financing - all on the Inputs sheet.
B8: • Base / Bull / Bear scenario switch (Inputs!D8). Interest is calculated on opening balances so the model has no circular references.
B9: • FCFF DCF with CAPM-based WACC, Gordon-growth terminal value, YEARFRAC discounting and a WACC x growth sensitivity grid.
B10: • Automated integrity checks (balance sheet, cash, equity roll-forward, valuation) roll up to a single status flag.
A12: # | B12: Key outputs (live)
B13: Active scenario | D13: =Inputs!D9 -> Base
B14: Revenue CAGR FY25A-FY30E | D14: =(IS!M7/IS!H7)^(1/(IS!M5-IS!H5))-1 -> 0.078984224
B15: EBITDA margin FY30E | D15: =IS!M13/IS!M7 -> 0.333
B16: EPS FY30E (Rs) | D16: =IS!M21 -> 22.688968
B17: WACC | D17: =DCF!E21 -> 0.12542146
B18: Enterprise value (Rs cr) | D18: =DCF!E41 -> 246137.06
B19: Equity value (Rs cr) | D19: =DCF!E44 -> 283737.06
B20: Intrinsic value per share (Rs) | D20: =DCF!E46 -> 226.8082
B21: Upside / (downside) vs market cap | D21: =DCF!E49 -> -0.15017233
B22: Model integrity status | D22: =Checks!D16 -> ALL PASS
A24: # | B24: Model index
B25: Inputs | D25: All assumptions, historical data, scenario levers
B26: IS | D26: Income statement + common-size analysis
B27: BS | D27: Balance sheet with balance check
B28: CF | D28: Cash flow statement
B29: Ratios | D29: Profitability, returns, liquidity, working capital
B30: DCF | D30: WACC, FCFF, terminal value, sensitivity
B31: Checks | D31: Model integrity checks
A33: # | B33: Modelling standards applied
B34: • Blue font = hard-coded input | Black = formula | Green = link to another sheet | Yellow fill = key lever.
B35: • Numbers: #,##0.0;(#,##0.0) | Percentages 2 d.p. | Years formatted 0"A" (actual) / 0"E" (estimate).
B36: • Base year hard-coded once; every later year = previous + 1. No constant is hard-coded in more than one place.
B37: • Partial anchoring (D$7) in common-size formulas; grouped rows instead of hidden rows; gridlines off; frozen headers.
B38: • Column A margin with '#' section anchors (Ctrl+Arrow navigation); dynamic sheet titles linked to the company name cell.
A40: # | B40: Important data note
B41: Reported ITC figures (FY22 and FY25 revenue, EBITDA, PBT) are sourced and cited on the Inputs sheet. Cost splits, FY23-24, the opening balance
B42: sheet and market inputs are analyst estimates: reconcile them to ITC's audited annual reports before using this model for any real decision.
A44: # | B44: Trend summary
B45: Fiscal year | D45: =IS!D5 -> 2021 | E45: =IS!E5 -> 2022 | F45: =IS!F5 -> 2023 | G45: =IS!G5 -> 2024 | H45: =IS!H5 -> 2025 | I45: =IS!I5 -> 2026 | J45: =IS!J5 -> 2027 | K45: =IS!K5 -> 2028 | ... M45: =IS!M5 -> 2030
B46: Revenue (Rs cr) | D46: =IS!D7 -> 48168 | E46: =IS!E7 -> 59101 | F46: =IS!F7 -> 69446 | G46: =IS!G7 -> 70867 | H46: =IS!H7 -> 73465 | I46: =IS!I7 -> 79709.525 | J46: =IS!J7 -> 86484.835 | K46: =IS!K7 -> 93403.621 | ... M46: =IS!M7 -> 107437.52
B47: EBITDA (Rs cr) | D47: =IS!D13 -> 15330 | E47: =IS!E13 -> 18934 | F47: =IS!F13 -> 22470 | G47: =IS!G13 -> 23050 | H47: =IS!H13 -> 24025 | I47: =IS!I13 -> 26144.724 | J47: =IS!J13 -> 28453.511 | K47: =IS!K13 -> 31010.002 | ... M47: =IS!M13 -> 35776.693
...

Sheet Inputs
B2: Inputs & Assumptions
B3: All hard-coded inputs live here (blue font). Yellow = key levers. Column O documents source / status of each input.
A4: # | B4: General settings
B5: Company name | D5: ITC Limited | O5: Change this cell: every sheet title updates automatically (dynamic titles).
B6: Reporting currency / unit | D6: INR crore (Rs cr) | O6: 1 crore = 10 million
B7: First historical fiscal year (FY ends 31-Mar) | D7: 2021 | O7: Timeline base year is hard-coded once; all other years = previous + 1.
B8: Scenario selector (1 = Base, 2 = Bull, 3 = Bear) | D8: 1 | O8: KEY LEVER. Change to 2 or 3 and the whole model, DCF and dashboard re-compute.
B9: Active scenario | D9: =CHOOSE(D8,"Base","Bull","Bear") -> Base
B10: Forecast effective tax rate | D10: 0.2517 | O10: Assumption: Indian corporate tax rate under Sec 115BAA (25.17% incl. surcharge & cess).
B11: Shares outstanding (crore) | D11: 1251 | O11: Approximation (~12.5 bn shares). Verify against latest ITC shareholding pattern.
B12: Valuation date (base balance sheet date) | D12: 45747 | O12: Set to the last actual balance sheet. Roll forward when FY26 actuals are loaded.
B13: Current market capitalisation (Rs cr) | D13: 333876 | O13: Source: Screener.in ITC page (consolidated), retrieved 28-Sep-2026. Update before use.
B14: Dividend payout ratio (% of net income) | D14: 0.85 | O14: Assumption based on ITC's historically high payout policy. Verify.
A16: # | B16: Timeline
B17: Fiscal year ending 31-Mar | C17: Unit | D17: =D7 -> 2021 | E17: =D17+1 -> 2022 | F17: =E17+1 -> 2023 | G17: =F17+1 -> 2024 | H17: =G17+1 -> 2025 | I17: =H17+1 -> 2026 | J17: =I17+1 -> 2027 | K17: =J17+1 -> 2028 | L17: =K17+1 -> 2029 | M17: =L17+1 -> 2030
A18: # | B18: Historical income statement inputs (Rs cr)
B19: Gross revenue | C19: Rs cr | D19: 48168 | E19: 59101 | F19: 69446 | G19: 70867 | H19: 73465 | O19: FY22 (59,101) and FY25 (73,465) reported; FY21 back-derived from reported +22.7% FY22 growth; FY23-24 analyst estimates. Sources: Business Standard 19-May-2022; ITC Q4 FY25 press release 22-May-2025.
B20: Cost of goods sold | C20: Rs cr | D20: 22735 | E20: 27541 | F20: 32153 | G20: 32670 | H20: 33720 | O20: ANALYST ESTIMATE of cost split - reconcile to Annual Report.
B21: Employee cost | C21: Rs cr | D21: 2697 | E21: 3132 | F21: 3403 | G21: 3402 | H21: 3453 | O21: ANALYST ESTIMATE - reconcile to Annual Report.
B22: Other operating expenses | C22: Rs cr | D22: 7406 | E22: 9494 | F22: 11420 | G22: 11745 | H22: 12267 | O22: Balancing item so that EBITDA ties to reported FY22 (18,934) and FY25 (24,025); other years estimated.
B23: Depreciation & amortisation | C23: Rs cr | D23: 1450 | E23: 1650 | F23: 1650 | G23: 1700 | H23: 1750 | O23: ANALYST ESTIMATE - reconcile to Annual Report.
B24: Other income | C24: Rs cr | D24: 2800 | E24: 2600 | F24: 3100 | G24: 3500 | H24: 3786 | O24: FY22 and FY25 set so PBT ties to reported (19,829 / 26,001); other years estimated.
B25: Interest expense | C25: Rs cr | D25: 70 | E25: 55 | F25: 50 | G25: 55 | H25: 60 | O25: ANALYST ESTIMATE - reconcile to Annual Report.
B26: Effective tax rate | C26: % | D26: 0.245 | E26: 0.2406 | F26: 0.245 | G26: 0.245 | H26: 0.245 | O26: FY22 rate ties to reported PAT of 15,058; others estimated.
A28: # | B28: Forecast drivers - Base case (all inputs)
B30: Revenue growth | C30: % | I30: 0.085 | J30: 0.085 | K30: 0.08 | L30: 0.075 | M30: 0.07 | O30: Assumption: high-single-digit growth, consistent with FY22-FY25 trend (see IS).
B31: COGS % of revenue | C31: % | I31: 0.458 | J31: 0.457 | K31: 0.456 | L31: 0.455 | M31: 0.455
B32: Employee cost % of revenue | C32: % | I32: 0.047 | J32: 0.047 | K32: 0.046 | L32: 0.046 | M32: 0.046
B33: Other opex % of revenue | C33: % | I33: 0.167 | J33: 0.167 | K33: 0.166 | L33: 0.166 | M33: 0.166
A35: # | B35: Scenario adjustments (added to Base case)
D36: Base | E36: Bull | F36: Bear
B37: Revenue growth adjustment | C37: pp | D37: 0 | E37: 0.02 | F37: -0.03
B38: COGS % adjustment | C38: pp | D38: 0 | E38: -0.01 | F38: 0.015
A40: # | B40: Live drivers (formulas - active scenario)
B41: Revenue growth - live | C41: % | I41: =I30+INDEX($D$37:$F$37,$D$8) -> 0.085 | J41: =J30+INDEX($D$37:$F$37,$D$8) -> 0.085 | K41: =K30+INDEX($D$37:$F$37,$D$8) -> 0.08 | L41: =L30+INDEX($D$37:$F$37,$D$8) -> 0.075 | M41: =M30+INDEX($D$37:$F$37,$D$8) -> 0.07
B42: COGS % of revenue - live | C42: % | I42: =I31+INDEX($D$38:$F$38,$D$8) -> 0.458 | J42: =J31+INDEX($D$38:$F$38,$D$8) -> 0.457 | K42: =K31+INDEX($D$38:$F$38,$D$8) -> 0.456 | L42: =L31+INDEX($D$38:$F$38,$D$8) -> 0.455 | M42: =M31+INDEX($D$38:$F$38,$D$8) -> 0.455
A44: # | B44: Other operating, capex & balance sheet drivers
B45: D&A % of opening net PPE | C45: % | I45: 0.07 | J45: 0.07 | K45: 0.07 | L45: 0.07 | M45: 0.07 | O45: Forecast drivers are analyst assumptions calibrated to base-year (FY25A) ratios.
B46: Capex % of revenue | C46: % | I46: 0.035 | J46: 0.035 | K46: 0.035 | L46: 0.035 | M46: 0.035
B47: Receivable days (on revenue) | C47: days | I47: 18 | J47: 18 | K47: 18 | L47: 18 | M47: 18
...

Sheet IS
B2: ="Income Statement - "&Inputs!$D$5 -> Income Statement - ITC Limited
B3: =Inputs!$D$6&" | Scenario: "&Inputs!$D$9 -> INR crore (Rs cr) | Scenario: Base
B5: Fiscal year ending 31-Mar | C5: Unit | D5: =Inputs!$D$7 -> 2021 | E5: =D5+1 -> 2022 | F5: =E5+1 -> 2023 | G5: =F5+1 -> 2024 | H5: =G5+1 -> 2025 | I5: =H5+1 -> 2026 | J5: =I5+1 -> 2027 | K5: =J5+1 -> 2028 | L5: =K5+1 -> 2029 | M5: =L5+1 -> 2030
A6: # | B6: Income statement
B7: Revenue | C7: Rs cr | D7: =Inputs!D19 -> 48168 | E7: =Inputs!E19 -> 59101 | F7: =Inputs!F19 -> 69446 | G7: =Inputs!G19 -> 70867 | H7: =Inputs!H19 -> 73465 | I7: =H7*(1+Inputs!I41) -> 79709.525 | J7: =I7*(1+Inputs!J41) -> 86484.835 | K7: =J7*(1+Inputs!K41) -> 93403.621 | L7: =K7*(1+Inputs!L41) -> 100408.89 | M7: =L7*(1+Inputs!M41) -> 107437.52
B8: growth % | C8: % | E8: =E7/D7-1 -> 0.22697642 | F8: =F7/E7-1 -> 0.17503934 | G8: =G7/F7-1 -> 0.020461942 | H8: =H7/G7-1 -> 0.036660223 | I8: =I7/H7-1 -> 0.085 | J8: =J7/I7-1 -> 0.085 | K8: =K7/J7-1 -> 0.08 | L8: =L7/K7-1 -> 0.075 | M8: =M7/L7-1 -> 0.07
B9: Cost of goods sold | C9: Rs cr | D9: =Inputs!D20 -> 22735 | E9: =Inputs!E20 -> 27541 | F9: =Inputs!F20 -> 32153 | G9: =Inputs!G20 -> 32670 | H9: =Inputs!H20 -> 33720 | I9: =I7*Inputs!I42 -> 36506.962 | J9: =J7*Inputs!J42 -> 39523.569 | K9: =K7*Inputs!K42 -> 42592.051 | L9: =L7*Inputs!L42 -> 45686.046 | M9: =M7*Inputs!M42 -> 48884.07
B10: Gross profit | C10: Rs cr | D10: =D7-D9 -> 25433 | E10: =E7-E9 -> 31560 | F10: =F7-F9 -> 37293 | G10: =G7-G9 -> 38197 | H10: =H7-H9 -> 39745 | I10: =I7-I9 -> 43202.563 | J10: =J7-J9 -> 46961.265 | K10: =K7-K9 -> 50811.57 | ... M10: =M7-M9 -> 58553.446
B11: Employee cost | C11: Rs cr | D11: =Inputs!D21 -> 2697 | E11: =Inputs!E21 -> 3132 | F11: =Inputs!F21 -> 3403 | G11: =Inputs!G21 -> 3402 | H11: =Inputs!H21 -> 3453 | I11: =I7*Inputs!I32 -> 3746.3477 | J11: =J7*Inputs!J32 -> 4064.7872 | K11: =K7*Inputs!K32 -> 4296.5666 | L11: =L7*Inputs!L32 -> 4618.8091 | M11: =M7*Inputs!M32 -> 4942.1257
B12: Other operating expenses | C12: Rs cr | D12: =Inputs!D22 -> 7406 | E12: =Inputs!E22 -> 9494 | F12: =Inputs!F22 -> 11420 | G12: =Inputs!G22 -> 11745 | H12: =Inputs!H22 -> 12267 | I12: =I7*Inputs!I33 -> 13311.491 | J12: =J7*Inputs!J33 -> 14442.967 | K12: =K7*Inputs!K33 -> 15505.001 | L12: =L7*Inputs!L33 -> 16667.876 | M12: =M7*Inputs!M33 -> 17834.628
B13: EBITDA | C13: Rs cr | D13: =D10-D11-D12 -> 15330 | E13: =E10-E11-E12 -> 18934 | F13: =F10-F11-F12 -> 22470 | G13: =G10-G11-G12 -> 23050 | H13: =H10-H11-H12 -> 24025 | I13: =I10-I11-I12 -> 26144.724 | J13: =J10-J11-J12 -> 28453.511 | K13: =K10-K11-K12 -> 31010.002 | ... M13: =M10-M11-M12 -> 35776.693
B14: Depreciation & amortisation | C14: Rs cr | D14: =Inputs!D23 -> 1450 | E14: =Inputs!E23 -> 1650 | F14: =Inputs!F23 -> 1650 | G14: =Inputs!G23 -> 1700 | H14: =Inputs!H23 -> 1750 | I14: =Inputs!I45*BS!H13 -> 1680 | J14: =Inputs!J45*BS!I13 -> 1757.6883 | K14: =Inputs!K45*BS!J13 -> 1846.538 | L14: =Inputs!L45*BS!K13 -> 1946.1192 | M14: =Inputs!M45*BS!L13 -> 2055.8927
B15: EBIT | C15: Rs cr | D15: =D13-D14 -> 13880 | E15: =E13-E14 -> 17284 | F15: =F13-F14 -> 20820 | G15: =G13-G14 -> 21350 | H15: =H13-H14 -> 22275 | I15: =I13-I14 -> 24464.724 | J15: =J13-J14 -> 26695.822 | K15: =K13-K14 -> 29163.464 | ... M15: =M13-M14 -> 33720.8
B16: Other income | C16: Rs cr | D16: =Inputs!D24 -> 2800 | E16: =Inputs!E24 -> 2600 | F16: =Inputs!F24 -> 3100 | G16: =Inputs!G24 -> 3500 | H16: =Inputs!H24 -> 3786 | I16: =Inputs!I52*BS!H8 -> 3610 | J16: =Inputs!J52*BS!I8 -> 3746.0171 | K16: =Inputs!K52*BS!J8 -> 3888.4084 | L16: =Inputs!L52*BS!K8 -> 4043.2567 | M16: =Inputs!M52*BS!L8 -> 4210.3757
B17: Interest expense | C17: Rs cr | D17: =Inputs!D25 -> 70 | E17: =Inputs!E25 -> 55 | F17: =Inputs!F25 -> 50 | G17: =Inputs!G25 -> 55 | H17: =Inputs!H25 -> 60 | I17: =Inputs!I53*BS!H21 -> 32 | J17: =Inputs!J53*BS!I21 -> 24 | K17: =Inputs!K53*BS!J21 -> 16 | L17: =Inputs!L53*BS!K21 -> 8 | M17: =Inputs!M53*BS!L21 -> 0
B18: Profit before tax | C18: Rs cr | D18: =D15+D16-D17 -> 16610 | E18: =E15+E16-E17 -> 19829 | F18: =F15+F16-F17 -> 23870 | G18: =G15+G16-G17 -> 24795 | H18: =H15+H16-H17 -> 26001 | I18: =I15+I16-I17 -> 28042.724 | J18: =J15+J16-J17 -> 30417.839 | K18: =K15+K16-K17 -> 33035.873 | ... M18: =M15+M16-M17 -> 37931.176
B19: Tax | C19: Rs cr | D19: =D18*Inputs!D26 -> 4069.45 | E19: =E18*Inputs!E26 -> 4770.8574 | F19: =F18*Inputs!F26 -> 5848.15 | G19: =G18*Inputs!G26 -> 6074.775 | H19: =H18*Inputs!H26 -> 6370.245 | I19: =I18*Inputs!$D$10 -> 7058.3537 | J19: =J18*Inputs!$D$10 -> 7656.1702 | K19: =K18*Inputs!$D$10 -> 8315.1292 | L19: =L18*Inputs!$D$10 -> 8941.7177 | M19: =M18*Inputs!$D$10 -> 9547.2769
B20: Net income | C20: Rs cr | D20: =D18-D19 -> 12540.55 | E20: =E18-E19 -> 15058.143 | F20: =F18-F19 -> 18021.85 | G20: =G18-G19 -> 18720.225 | H20: =H18-H19 -> 19630.755 | I20: =I18-I19 -> 20984.371 | J20: =J18-J19 -> 22761.669 | K20: =K18-K19 -> 24720.744 | ... M20: =M18-M19 -> 28383.899
B21: EPS | C21: Rs | D21: =D20/Inputs!$D$11 -> 10.02442 | E21: =E20/Inputs!$D$11 -> 12.036885 | F21: =F20/Inputs!$D$11 -> 14.405955 | G21: =G20/Inputs!$D$11 -> 14.964209 | H21: =H20/Inputs!$D$11 -> 15.69205 | I21: =I20/Inputs!$D$11 -> 16.774077 | J21: =J20/Inputs!$D$11 -> 18.19478 | K21: =K20/Inputs!$D$11 -> 19.760786 | ... M21: =M20/Inputs!$D$11 -> 22.688968
A24: # | B24: Common-size income statement (% of revenue)
B25: COGS | C25: % | D25: =D9/D$7 -> 0.47199385 | E25: =E9/E$7 -> 0.46599888 | F25: =F9/F$7 -> 0.46299283 | G25: =G9/G$7 -> 0.46100442 | H25: =H9/H$7 -> 0.45899408 | I25: =I9/I$7 -> 0.458 | J25: =J9/J$7 -> 0.457 | K25: =K9/K$7 -> 0.456 | ... M25: =M9/M$7 -> 0.455
B26: Gross margin | C26: % | D26: =D10/D$7 -> 0.52800615 | E26: =E10/E$7 -> 0.53400112 | F26: =F10/F$7 -> 0.53700717 | G26: =G10/G$7 -> 0.53899558 | H26: =H10/H$7 -> 0.54100592 | I26: =I10/I$7 -> 0.542 | J26: =J10/J$7 -> 0.543 | K26: =K10/K$7 -> 0.544 | ... M26: =M10/M$7 -> 0.545
B27: Employee cost | C27: % | D27: =D11/D$7 -> 0.05599153 | E27: =E11/E$7 -> 0.052994027 | F27: =F11/F$7 -> 0.049002102 | G27: =G11/G$7 -> 0.048005419 | H27: =H11/H$7 -> 0.047001974 | I27: =I11/I$7 -> 0.047 | J27: =J11/J$7 -> 0.047 | K27: =K11/K$7 -> 0.046 | ... M27: =M11/M$7 -> 0.046
B28: Other operating expenses | C28: % | D28: =D12/D$7 -> 0.15375353 | E28: =E12/E$7 -> 0.16064026 | F28: =F12/F$7 -> 0.16444432 | G28: =G12/G$7 -> 0.16573299 | H28: =H12/H$7 -> 0.16697747 | I28: =I12/I$7 -> 0.167 | J28: =J12/J$7 -> 0.167 | K28: =K12/K$7 -> 0.166 | ... M28: =M12/M$7 -> 0.166
B29: EBITDA margin | C29: % | D29: =D13/D$7 -> 0.31826109 | E29: =E13/E$7 -> 0.32036683 | F29: =F13/F$7 -> 0.32356075 | G29: =G13/G$7 -> 0.32525717 | H29: =H13/H$7 -> 0.32702648 | I29: =I13/I$7 -> 0.328 | J29: =J13/J$7 -> 0.329 | K29: =K13/K$7 -> 0.332 | ... M29: =M13/M$7 -> 0.333
B30: D&A | C30: % | D30: =D14/D$7 -> 0.030102973 | E30: =E14/E$7 -> 0.027918309 | F30: =F14/F$7 -> 0.023759468 | G30: =G14/G$7 -> 0.023988598 | H30: =H14/H$7 -> 0.023820867 | I30: =I14/I$7 -> 0.021076528 | J30: =J14/J$7 -> 0.02032366 | K30: =K14/K$7 -> 0.019769448 | ... M30: =M14/M$7 -> 0.019135705
B31: EBIT margin | C31: % | D31: =D15/D$7 -> 0.28815811 | E31: =E15/E$7 -> 0.29244852 | F31: =F15/F$7 -> 0.29980128 | G31: =G15/G$7 -> 0.30126857 | H31: =H15/H$7 -> 0.30320561 | I31: =I15/I$7 -> 0.30692347 | J31: =J15/J$7 -> 0.30867634 | K31: =K15/K$7 -> 0.31223055 | ... M31: =M15/M$7 -> 0.31386429
B32: Other income | C32: % | D32: =D16/D$7 -> 0.058129879 | E32: =E16/E$7 -> 0.043992487 | F32: =F16/F$7 -> 0.044639 | G32: =G16/G$7 -> 0.049388291 | H32: =H16/H$7 -> 0.051534744 | I32: =I16/I$7 -> 0.045289443 | J32: =J16/J$7 -> 0.04331415 | K32: =K16/K$7 -> 0.041630167 | ... M32: =M16/M$7 -> 0.039189064
B33: Interest expense | C33: % | D33: =D17/D$7 -> 0.001453247 | E33: =E17/E$7 -> 0.00093061031 | F33: =F17/F$7 -> 0.00071998387 | G33: =G17/G$7 -> 0.00077610171 | H33: =H17/H$7 -> 0.00081671544 | I33: =I17/I$7 -> 0.00040145767 | J33: =J17/J$7 -> 0.0002775053 | K33: =K17/K$7 -> 0.00017129957 | ... M33: =M17/M$7 -> 0
B34: PBT margin | C34: % | D34: =D18/D$7 -> 0.34483475 | E34: =E18/E$7 -> 0.3355104 | F34: =F18/F$7 -> 0.3437203 | G34: =G18/G$7 -> 0.34988076 | H34: =H18/H$7 -> 0.35392364 | I34: =I18/I$7 -> 0.35181146 | J34: =J18/J$7 -> 0.35171299 | K34: =K18/K$7 -> 0.35368942 | ... M34: =M18/M$7 -> 0.35305336
B35: Tax | C35: % | D35: =D19/D$7 -> 0.084484513 | E35: =E19/E$7 -> 0.080723802 | F35: =F19/F$7 -> 0.084211474 | G35: =G19/G$7 -> 0.085720787 | H35: =H19/H$7 -> 0.086711291 | I35: =I19/I$7 -> 0.088550944 | J35: =J19/J$7 -> 0.088526158 | K35: =K19/K$7 -> 0.089023627 | ... M35: =M19/M$7 -> 0.08886353
B36: Net margin | C36: % | D36: =D20/D$7 -> 0.26035023 | E36: =E20/E$7 -> 0.2547866 | F36: =F20/F$7 -> 0.25950883 | G36: =G20/G$7 -> 0.26415998 | H36: =H20/H$7 -> 0.26721235 | I36: =I20/I$7 -> 0.26326051 | J36: =J20/J$7 -> 0.26318683 | K36: =K20/K$7 -> 0.26466579 | ... M36: =M20/M$7 -> 0.26418983

Sheet BS
B2: ="Balance Sheet - "&Inputs!$D$5 -> Balance Sheet - ITC Limited
B3: =Inputs!$D$6&" | Scenario: "&Inputs!$D$9 -> INR crore (Rs cr) | Scenario: Base
B5: Fiscal year ending 31-Mar | C5: Unit | D5: =Inputs!$D$7 -> 2021 | E5: =D5+1 -> 2022 | F5: =E5+1 -> 2023 | G5: =F5+1 -> 2024 | H5: =G5+1 -> 2025 | I5: =H5+1 -> 2026 | J5: =I5+1 -> 2027 | K5: =J5+1 -> 2028 | L5: =K5+1 -> 2029 | M5: =L5+1 -> 2030
A7: # | B7: Assets
B8: Cash & investments | C8: Rs cr | H8: =Inputs!H58 -> 38000 | I8: =CF!I25 -> 39431.759 | J8: =CF!J25 -> 40930.614 | K8: =CF!K25 -> 42560.596 | L8: =CF!L25 -> 44319.744 | M8: =CF!M25 -> 46294.154
B9: Inventories | C9: Rs cr | H9: =Inputs!H61 -> 12500 | I9: =Inputs!I48*IS!I9/365 -> 13502.575 | J9: =Inputs!J48*IS!J9/365 -> 14618.306 | K9: =Inputs!K48*IS!K9/365 -> 15753.224 | L9: =Inputs!L48*IS!L9/365 -> 16897.579 | M9: =Inputs!M48*IS!M9/365 -> 18080.409
B10: Trade receivables | C10: Rs cr | H10: =Inputs!H62 -> 3600 | I10: =Inputs!I47*IS!I7/365 -> 3930.8807 | J10: =Inputs!J47*IS!J7/365 -> 4265.0055 | K10: =Inputs!K47*IS!K7/365 -> 4606.206 | L10: =Inputs!L47*IS!L7/365 -> 4951.6714 | M10: =Inputs!M47*IS!M7/365 -> 5298.2884
B11: Other current assets | C11: Rs cr | H11: =Inputs!H63 -> 5500 | I11: =Inputs!I50*IS!I7 -> 5978.2144 | J11: =Inputs!J50*IS!J7 -> 6486.3626 | K11: =Inputs!K50*IS!K7 -> 7005.2716 | L11: =Inputs!L50*IS!L7 -> 7530.667 | M11: =Inputs!M50*IS!M7 -> 8057.8137
B12: Total current assets | C12: Rs cr | H12: =SUM(H8:H11) -> 59600 | I12: =SUM(I8:I11) -> 62843.429 | J12: =SUM(J8:J11) -> 66300.289 | K12: =SUM(K8:K11) -> 69925.299 | L12: =SUM(L8:L11) -> 73699.661 | M12: =SUM(M8:M11) -> 77730.665
B13: Net PPE incl. CWIP | C13: Rs cr | H13: =Inputs!H59 -> 24000 | I13: =H13-CF!I16-IS!I14 -> 25109.833 | J13: =I13-CF!J16-IS!J14 -> 26379.114 | K13: =J13-CF!K16-IS!K14 -> 27801.703 | L13: =K13-CF!L16-IS!L14 -> 29369.895 | M13: =L13-CF!M16-IS!M14 -> 31074.315
B14: Intangibles & other non-current assets | C14: Rs cr | H14: =Inputs!H60 -> 6000 | I14: =H14 -> 6000 | J14: =I14 -> 6000 | K14: =J14 -> 6000 | L14: =K14 -> 6000 | M14: =L14 -> 6000
B15: Total non-current assets | C15: Rs cr | H15: =H13+H14 -> 30000 | I15: =I13+I14 -> 31109.833 | J15: =J13+J14 -> 32379.114 | K15: =K13+K14 -> 33801.703 | L15: =L13+L14 -> 35369.895 | M15: =M13+M14 -> 37074.315
B16: Total assets | C16: Rs cr | H16: =H12+H15 -> 89600 | I16: =I12+I15 -> 93953.262 | J16: =J12+J15 -> 98679.403 | K16: =K12+K15 -> 103727 | L16: =L12+L15 -> 109069.56 | M16: =M12+M15 -> 114804.98
A18: # | B18: Liabilities & equity
B19: Trade payables | C19: Rs cr | H19: =Inputs!H64 -> 6500 | I19: =Inputs!I49*IS!I9/365 -> 7001.3353 | J19: =Inputs!J49*IS!J9/365 -> 7579.8626 | K19: =Inputs!K49*IS!K9/365 -> 8168.3386 | L19: =Inputs!L49*IS!L9/365 -> 8761.7075 | M19: =Inputs!M49*IS!M9/365 -> 9375.027
B20: Other current liabilities | C20: Rs cr | H20: =Inputs!H65 -> 9000 | I20: =Inputs!I51*IS!I7 -> 9804.2716 | J20: =Inputs!J51*IS!J7 -> 10637.635 | K20: =Inputs!K51*IS!K7 -> 11488.645 | L20: =Inputs!L51*IS!L7 -> 12350.294 | M20: =Inputs!M51*IS!M7 -> 13214.814
B21: Debt incl. lease liabilities | C21: Rs cr | H21: =Inputs!H66 -> 400 | I21: =MAX(0,H21-Inputs!I54) -> 300 | J21: =MAX(0,I21-Inputs!J54) -> 200 | K21: =MAX(0,J21-Inputs!K54) -> 100 | L21: =MAX(0,K21-Inputs!L54) -> 0 | M21: =MAX(0,L21-Inputs!M54) -> 0
B22: Other non-current liabilities | C22: Rs cr | H22: =Inputs!H67 -> 2000 | I22: =H22 -> 2000 | J22: =I22 -> 2000 | K22: =J22 -> 2000 | L22: =K22 -> 2000 | M22: =L22 -> 2000
B23: Total liabilities | C23: Rs cr | H23: =SUM(H19:H22) -> 17900 | I23: =SUM(I19:I22) -> 19105.607 | J23: =SUM(J19:J22) -> 20417.497 | K23: =SUM(K19:K22) -> 21756.984 | L23: =SUM(L19:L22) -> 23112.001 | M23: =SUM(M19:M22) -> 24589.841
B24: Shareholders' equity | C24: Rs cr | H24: =H16-H23 -> 71700 | I24: =H24+IS!I20+CF!I20 -> 74847.656 | J24: =I24+IS!J20+CF!J20 -> 78261.906 | K24: =J24+IS!K20+CF!K20 -> 81970.017 | L24: =K24+IS!L20+CF!L20 -> 85957.555 | M24: =L24+IS!M20+CF!M20 -> 90215.139
B25: Total liabilities & equity | C25: Rs cr | H25: =H23+H24 -> 89600 | I25: =I23+I24 -> 93953.262 | J25: =J23+J24 -> 98679.403 | K25: =K23+K24 -> 103727 | L25: =L23+L24 -> 109069.56 | M25: =M23+M24 -> 114804.98
B27: Balance check (assets - liabilities & equity) | C27: Rs cr | H27: =ROUND(H16-H25,3) -> 0 | I27: =ROUND(I16-I25,3) -> 0 | J27: =ROUND(J16-J25,3) -> 0 | K27: =ROUND(K16-K25,3) -> 0 | L27: =ROUND(L16-L25,3) -> 0 | M27: =ROUND(M16-M25,3) -> 0
B28: Status | H28: =IF(ABS(H27)<0.001,"OK","ERROR") -> OK | I28: =IF(ABS(I27)<0.001,"OK","ERROR") -> OK | J28: =IF(ABS(J27)<0.001,"OK","ERROR") -> OK | K28: =IF(ABS(K27)<0.001,"OK","ERROR") -> OK | L28: =IF(ABS(L27)<0.001,"OK","ERROR") -> OK | M28: =IF(ABS(M27)<0.001,"OK","ERROR") -> OK

Sheet CF
B2: ="Cash Flow Statement - "&Inputs!$D$5 -> Cash Flow Statement - ITC Limited
B3: =Inputs!$D$6&" | Scenario: "&Inputs!$D$9 -> INR crore (Rs cr) | Scenario: Base
B5: Fiscal year ending 31-Mar | C5: Unit | D5: =Inputs!$D$7 -> 2021 | E5: =D5+1 -> 2022 | F5: =E5+1 -> 2023 | G5: =F5+1 -> 2024 | H5: =G5+1 -> 2025 | I5: =H5+1 -> 2026 | J5: =I5+1 -> 2027 | K5: =J5+1 -> 2028 | L5: =K5+1 -> 2029 | M5: =L5+1 -> 2030
A6: # | B6: Operating activities
B7: Net income | C7: Rs cr | I7: =IS!I20 -> 20984.371 | J7: =IS!J20 -> 22761.669 | K7: =IS!K20 -> 24720.744 | L7: =IS!L20 -> 26583.581 | M7: =IS!M20 -> 28383.899
B8: Add: D&A | C8: Rs cr | I8: =IS!I14 -> 1680 | J8: =IS!J14 -> 1757.6883 | K8: =IS!K14 -> 1846.538 | L8: =IS!L14 -> 1946.1192 | M8: =IS!M14 -> 2055.8927
B9: (Increase)/decrease in receivables | C9: Rs cr | I9: =BS!H10-BS!I10 -> -330.88068 | J9: =BS!I10-BS!J10 -> -334.12486 | K9: =BS!J10-BS!K10 -> -341.20044 | L9: =BS!K10-BS!L10 -> -345.46545 | M9: =BS!L10-BS!M10 -> -346.617
B10: (Increase)/decrease in inventories | C10: Rs cr | I10: =BS!H9-BS!I9 -> -1002.5752 | J10: =BS!I9-BS!J9 -> -1115.7313 | K10: =BS!J9-BS!K9 -> -1134.918 | L10: =BS!K9-BS!L9 -> -1144.3543 | M10: =BS!L9-BS!M9 -> -1182.8305
B11: (Increase)/decrease in other current assets | C11: Rs cr | I11: =BS!H11-BS!I11 -> -478.21438 | J11: =BS!I11-BS!J11 -> -508.14822 | K11: =BS!J11-BS!K11 -> -518.90901 | L11: =BS!K11-BS!L11 -> -525.39537 | M11: =BS!L11-BS!M11 -> -527.14669
B12: Increase/(decrease) in payables | C12: Rs cr | I12: =BS!I19-BS!H19 -> 501.33526 | J12: =BS!J19-BS!I19 -> 578.52736 | K12: =BS!K19-BS!J19 -> 588.47599 | L12: =BS!L19-BS!K19 -> 593.3689 | M12: =BS!M19-BS!L19 -> 613.31953
B13: Increase/(decrease) in other current liabilities | C13: Rs cr | I13: =BS!I20-BS!H20 -> 804.27157 | J13: =BS!J20-BS!I20 -> 833.36308 | K13: =BS!K20-BS!J20 -> 851.01077 | L13: =BS!L20-BS!K20 -> 861.64841 | M13: =BS!M20-BS!L20 -> 864.52057
B14: Cash flow from operations | C14: Rs cr | I14: =SUM(I7:I13) -> 22158.307 | J14: =SUM(J7:J13) -> 23973.244 | K14: =SUM(K7:K13) -> 26011.741 | L14: =SUM(L7:L13) -> 27969.503 | M14: =SUM(M7:M13) -> 29861.037
A15: # | B15: Investing activities
B16: Capital expenditure | C16: Rs cr | I16: =-Inputs!I46*IS!I7 -> -2789.8334 | J16: =-Inputs!J46*IS!J7 -> -3026.9692 | K16: =-Inputs!K46*IS!K7 -> -3269.1267 | L16: =-Inputs!L46*IS!L7 -> -3514.3113 | M16: =-Inputs!M46*IS!M7 -> -3760.313
B17: Cash flow from investing | C17: Rs cr | I17: =I16 -> -2789.8334 | J17: =J16 -> -3026.9692 | K17: =K16 -> -3269.1267 | L17: =L16 -> -3514.3113 | M17: =M16 -> -3760.313
A18: # | B18: Financing activities
B19: Debt drawdown/(repayment) | C19: Rs cr | I19: =BS!I21-BS!H21 -> -100 | J19: =BS!J21-BS!I21 -> -100 | K19: =BS!K21-BS!J21 -> -100 | L19: =BS!L21-BS!K21 -> -100 | M19: =BS!M21-BS!L21 -> 0
B20: Dividends paid | C20: Rs cr | I20: =-IS!I20*Inputs!$D$14 -> -17836.715 | J20: =-IS!J20*Inputs!$D$14 -> -19347.419 | K20: =-IS!K20*Inputs!$D$14 -> -21012.632 | L20: =-IS!L20*Inputs!$D$14 -> -22596.044 | M20: =-IS!M20*Inputs!$D$14 -> -24126.314
B21: Cash flow from financing | C21: Rs cr | I21: =I19+I20 -> -17936.715 | J21: =J19+J20 -> -19447.419 | K21: =K19+K20 -> -21112.632 | L21: =L19+L20 -> -22696.044 | M21: =M19+M20 -> -24126.314
A22: # | B22: Net cash movement
B23: Net change in cash | C23: Rs cr | I23: =I14+I17+I21 -> 1431.7588 | J23: =J14+J17+J21 -> 1498.8555 | K23: =K14+K17+K21 -> 1629.9821 | L23: =L14+L17+L21 -> 1759.1473 | M23: =M14+M17+M21 -> 1974.4103
B24: Opening cash & investments | C24: Rs cr | I24: =BS!H8 -> 38000 | J24: =BS!I8 -> 39431.759 | K24: =BS!J8 -> 40930.614 | L24: =BS!K8 -> 42560.596 | M24: =BS!L8 -> 44319.744
B25: Closing cash & investments | C25: Rs cr | I25: =I24+I23 -> 39431.759 | J25: =J24+J23 -> 40930.614 | K25: =K24+K23 -> 42560.596 | L25: =L24+L23 -> 44319.744 | M25: =M24+M23 -> 46294.154

Sheet Ratios
B2: ="Ratio Analysis - "&Inputs!$D$5 -> Ratio Analysis - ITC Limited
B3: =Inputs!$D$6&" | Scenario: "&Inputs!$D$9 -> INR crore (Rs cr) | Scenario: Base
B5: Fiscal year ending 31-Mar | C5: Unit | D5: =Inputs!$D$7 -> 2021 | E5: =D5+1 -> 2022 | F5: =E5+1 -> 2023 | G5: =F5+1 -> 2024 | H5: =G5+1 -> 2025 | I5: =H5+1 -> 2026 | J5: =I5+1 -> 2027 | K5: =J5+1 -> 2028 | L5: =K5+1 -> 2029 | M5: =L5+1 -> 2030
A7: # | B7: Growth & profitability
B8: Revenue growth | C8: % | E8: =IS!E8 -> 0.22697642 | F8: =IS!F8 -> 0.17503934 | G8: =IS!G8 -> 0.020461942 | H8: =IS!H8 -> 0.036660223 | I8: =IS!I8 -> 0.085 | J8: =IS!J8 -> 0.085 | K8: =IS!K8 -> 0.08 | L8: =IS!L8 -> 0.075 | M8: =IS!M8 -> 0.07
B9: EBITDA margin | C9: % | D9: =IS!D13/IS!D7 -> 0.31826109 | E9: =IS!E13/IS!E7 -> 0.32036683 | F9: =IS!F13/IS!F7 -> 0.32356075 | G9: =IS!G13/IS!G7 -> 0.32525717 | H9: =IS!H13/IS!H7 -> 0.32702648 | I9: =IS!I13/IS!I7 -> 0.328 | J9: =IS!J13/IS!J7 -> 0.329 | K9: =IS!K13/IS!K7 -> 0.332 | ... M9: =IS!M13/IS!M7 -> 0.333
B10: EBIT margin | C10: % | D10: =IS!D15/IS!D7 -> 0.28815811 | E10: =IS!E15/IS!E7 -> 0.29244852 | F10: =IS!F15/IS!F7 -> 0.29980128 | G10: =IS!G15/IS!G7 -> 0.30126857 | H10: =IS!H15/IS!H7 -> 0.30320561 | I10: =IS!I15/IS!I7 -> 0.30692347 | J10: =IS!J15/IS!J7 -> 0.30867634 | K10: =IS!K15/IS!K7 -> 0.31223055 | ... M10: =IS!M15/IS!M7 -> 0.31386429
B11: Net margin | C11: % | D11: =IS!D20/IS!D7 -> 0.26035023 | E11: =IS!E20/IS!E7 -> 0.2547866 | F11: =IS!F20/IS!F7 -> 0.25950883 | G11: =IS!G20/IS!G7 -> 0.26415998 | H11: =IS!H20/IS!H7 -> 0.26721235 | I11: =IS!I20/IS!I7 -> 0.26326051 | J11: =IS!J20/IS!J7 -> 0.26318683 | K11: =IS!K20/IS!K7 -> 0.26466579 | ... M11: =IS!M20/IS!M7 -> 0.26418983
B12: EPS | C12: Rs | D12: =IS!D21 -> 10.02442 | E12: =IS!E21 -> 12.036885 | F12: =IS!F21 -> 14.405955 | G12: =IS!G21 -> 14.964209 | H12: =IS!H21 -> 15.69205 | I12: =IS!I21 -> 16.774077 | J12: =IS!J21 -> 18.19478 | K12: =IS!K21 -> 19.760786 | ... M12: =IS!M21 -> 22.688968
B13: EPS growth | C13: % | E13: =IS!E21/IS!D21-1 -> 0.20075616 | F13: =IS!F21/IS!E21-1 -> 0.19681759 | G13: =IS!G21/IS!F21-1 -> 0.038751571 | H13: =IS!H21/IS!G21-1 -> 0.048638838 | I13: =IS!I21/IS!H21-1 -> 0.068953819 | J13: =IS!J21/IS!I21-1 -> 0.084696306 | K13: =IS!K21/IS!J21-1 -> 0.08606901 | L13: =IS!L21/IS!K21-1 -> 0.075355241 | M13: =IS!M21/IS!L21-1 -> 0.067722917
A14: # | B14: Returns
B15: Return on equity (avg equity) | C15: % | I15: =IS!I20/AVERAGE(BS!H24:I24) -> 0.28638289 | J15: =IS!J20/AVERAGE(BS!I24:J24) -> 0.29732525 | K15: =IS!K20/AVERAGE(BS!J24:K24) -> 0.30856203 | L15: =IS!L20/AVERAGE(BS!K24:L24) -> 0.3166077 | M15: =IS!M20/AVERAGE(BS!L24:M24) -> 0.32222813
B16: ROCE (EBIT / equity + debt) | C16: % | H16: =IS!H15/(BS!H24+BS!H21) -> 0.30894591 | I16: =IS!I15/(BS!I24+BS!I21) -> 0.32555539 | J16: =IS!J15/(BS!J24+BS!J21) -> 0.34023928 | K16: =IS!K15/(BS!K24+BS!K21) -> 0.35534858 | L16: =IS!L15/(BS!L24+BS!L21) -> 0.36634409 | M16: =IS!M15/(BS!M24+BS!M21) -> 0.37378205
A17: # | B17: Liquidity & leverage
B18: Current ratio | C18: x | H18: =BS!H12/(BS!H19+BS!H20) -> 3.8451613 | I18: =BS!I12/(BS!I19+BS!I20) -> 3.7394323 | J18: =BS!J12/(BS!J19+BS!J20) -> 3.6393742 | K18: =BS!K12/(BS!K19+BS!K20) -> 3.557275 | L18: =BS!L12/(BS!L19+BS!L20) -> 3.4908894 | M18: =BS!M12/(BS!M19+BS!M20) -> 3.4409567
B19: Net cash / (net debt) | C19: Rs cr | H19: =BS!H8-BS!H21 -> 37600 | I19: =BS!I8-BS!I21 -> 39131.759 | J19: =BS!J8-BS!J21 -> 40730.614 | K19: =BS!K8-BS!K21 -> 42460.596 | L19: =BS!L8-BS!L21 -> 44319.744 | M19: =BS!M8-BS!M21 -> 46294.154
B20: Net cash / EBITDA | C20: x | H20: =(BS!H8-BS!H21)/IS!H13 -> 1.5650364 | I20: =(BS!I8-BS!I21)/IS!I13 -> 1.4967363 | J20: =(BS!J8-BS!J21)/IS!J13 -> 1.4314794 | K20: =(BS!K8-BS!K21)/IS!K13 -> 1.3692549 | L20: =(BS!L8-BS!L21)/IS!L13 -> 1.3255033 | M20: =(BS!M8-BS!M21)/IS!M13 -> 1.2939752
A21: # | B21: Working capital efficiency
B22: Receivable days | C22: days | H22: =BS!H10/IS!H7*365 -> 17.886068 | I22: =BS!I10/IS!I7*365 -> 18 | J22: =BS!J10/IS!J7*365 -> 18 | K22: =BS!K10/IS!K7*365 -> 18 | L22: =BS!L10/IS!L7*365 -> 18 | M22: =BS!M10/IS!M7*365 -> 18
B23: Inventory days | C23: days | H23: =BS!H9/IS!H9*365 -> 135.30546 | I23: =BS!I9/IS!I9*365 -> 135 | J23: =BS!J9/IS!J9*365 -> 135 | K23: =BS!K9/IS!K9*365 -> 135 | L23: =BS!L9/IS!L9*365 -> 135 | M23: =BS!M9/IS!M9*365 -> 135
B24: Payable days | C24: days | H24: =BS!H19/IS!H9*365 -> 70.358837 | I24: =BS!I19/IS!I9*365 -> 70 | J24: =BS!J19/IS!J9*365 -> 70 | K24: =BS!K19/IS!K9*365 -> 70 | L24: =BS!L19/IS!L9*365 -> 70 | M24: =BS!M19/IS!M9*365 -> 70
B25: Cash conversion cycle | C25: days | H25: =H22+H23-H24 -> 82.832687 | I25: =I22+I23-I24 -> 83 | J25: =J22+J23-J24 -> 83 | K25: =K22+K23-K24 -> 83 | L25: =L22+L23-L24 -> 83 | M25: =M22+M23-M24 -> 83
A26: # | B26: Cash flow & payout
B27: FCFF | C27: Rs cr | I27: =DCF!I32 -> 16691.056 | J27: =DCF!J32 -> 18161.089 | K27: =DCF!K32 -> 19844.891 | L27: =DCF!L32 -> 21435.609 | M27: =DCF!M32 -> 22950.1
B28: FCFF / net income | C28: % | I28: =DCF!I32/IS!I20 -> 0.7954042 | J28: =DCF!J32/IS!J20 -> 0.79788037 | K28: =DCF!K32/IS!K20 -> 0.8027627 | L28: =DCF!L32/IS!L20 -> 0.80634767 | M28: =DCF!M32/IS!M20 -> 0.80856053
B29: Dividend payout ratio | C29: % | I29: =-CF!I20/IS!I20 -> 0.85 | J29: =-CF!J20/IS!J20 -> 0.85 | K29: =-CF!K20/IS!K20 -> 0.85 | L29: =-CF!L20/IS!L20 -> 0.85 | M29: =-CF!M20/IS!M20 -> 0.85

Sheet DCF
B2: ="DCF Valuation - "&Inputs!$D$5 -> DCF Valuation - ITC Limited
B3: =Inputs!$D$6&" | Scenario: "&Inputs!$D$9 -> INR crore (Rs cr) | Scenario: Base
A7: # | B7: Cost of capital (WACC)
B8: Risk-free rate (10Y G-Sec) | C8: % | D8: 0.066 | F8: Assumption - update with current 10Y Government of India bond yield.
B9: Equity risk premium | C9: % | D9: 0.07 | F9: Assumption - India ERP (e.g. Damodaran). Update.
B10: Equity beta | C10: x | D10: 0.85 | F10: Assumption - update with current regression / Bloomberg beta.
B11: Cost of equity (CAPM) | C11: % | D11: =D8+D10*D9 -> 0.1255
B12: Pre-tax cost of debt | C12: % | D12: 0.08
B13: Tax rate | C13: % | D13: =Inputs!D10 -> 0.2517
B14: After-tax cost of debt | C14: % | D14: =D12*(1-D13) -> 0.059864
B15: Market capitalisation | C15: Rs cr | D15: =Inputs!D13 -> 333876
B16: Debt (FY25A) | C16: Rs cr | D16: =BS!H21 -> 400
B18: Capital structure | D18: Weight | E18: Cost
B19: Equity | D19: =D15/(D15+D16) -> 0.99880338 | E19: =D11 -> 0.1255
B20: Debt | D20: =D16/(D15+D16) -> 0.001196616 | E20: =D14 -> 0.059864
B21: WACC (SUMPRODUCT of weights x costs) | C21: % | E21: =SUMPRODUCT(D19:D20,E19:E20) -> 0.12542146
B22: Terminal growth rate | C22: % | E22: 0.05
B23: Valuation date | E23: =Inputs!D12 -> 45747
A24: # | B24: Free cash flow to firm (FCFF)
B25: Fiscal year ending 31-Mar | C25: Unit | D25: =Inputs!$D$7 -> 2021 | E25: =D25+1 -> 2022 | F25: =E25+1 -> 2023 | G25: =F25+1 -> 2024 | H25: =G25+1 -> 2025 | I25: =H25+1 -> 2026 | J25: =I25+1 -> 2027 | K25: =J25+1 -> 2028 | L25: =K25+1 -> 2029 | M25: =L25+1 -> 2030
B26: EBIT | C26: Rs cr | I26: =IS!I15 -> 24464.724 | J26: =IS!J15 -> 26695.822 | K26: =IS!K15 -> 29163.464 | L26: =IS!L15 -> 31490.042 | M26: =IS!M15 -> 33720.8
B27: Less: tax on EBIT | C27: Rs cr | I27: =-I26*Inputs!$D$10 -> -6157.7711 | J27: =-J26*Inputs!$D$10 -> -6719.3385 | K27: =-K26*Inputs!$D$10 -> -7340.444 | L27: =-L26*Inputs!$D$10 -> -7926.0436 | M27: =-M26*Inputs!$D$10 -> -8487.5254
B28: NOPAT | C28: Rs cr | I28: =I26+I27 -> 18306.953 | J28: =J26+J27 -> 19976.484 | K28: =K26+K27 -> 21823.02 | L28: =L26+L27 -> 23563.999 | M28: =M26+M27 -> 25233.275
B29: Add: D&A | C29: Rs cr | I29: =IS!I14 -> 1680 | J29: =IS!J14 -> 1757.6883 | K29: =IS!K14 -> 1846.538 | L29: =IS!L14 -> 1946.1192 | M29: =IS!M14 -> 2055.8927
B30: Less: capex | C30: Rs cr | I30: =CF!I16 -> -2789.8334 | J30: =CF!J16 -> -3026.9692 | K30: =CF!K16 -> -3269.1267 | L30: =CF!L16 -> -3514.3113 | M30: =CF!M16 -> -3760.313
B31: Less: increase in net working capital | C31: Rs cr | I31: =SUM(CF!I9:I13) -> -506.06337 | J31: =SUM(CF!J9:J13) -> -546.11398 | K31: =SUM(CF!K9:K13) -> -555.54067 | L31: =SUM(CF!L9:L13) -> -560.19782 | M31: =SUM(CF!M9:M13) -> -578.75411
B32: Free cash flow to firm (FCFF) | C32: Rs cr | I32: =I28+I29+I30+I31 -> 16691.056 | J32: =J28+J29+J30+J31 -> 18161.089 | K32: =K28+K29+K30+K31 -> 19844.891 | L32: =L28+L29+L30+L31 -> 21435.609 | M32: =M28+M29+M30+M31 -> 22950.1
B33: Period end date | C33: date | I33: =DATE(I$25,3,31) -> 46112 | J33: =DATE(J$25,3,31) -> 46477 | K33: =DATE(K$25,3,31) -> 46843 | L33: =DATE(L$25,3,31) -> 47208 | M33: =DATE(M$25,3,31) -> 47573
B34: Discount period (years, YEARFRAC) | C34: yrs | I34: =YEARFRAC($E$23,I33) -> 1 | J34: =YEARFRAC($E$23,J33) -> 2 | K34: =YEARFRAC($E$23,K33) -> 3 | L34: =YEARFRAC($E$23,L33) -> 4 | M34: =YEARFRAC($E$23,M33) -> 5
B35: Discount factor | C35: x | I35: =1/(1+$E$21)^I34 -> 0.88855601 | J35: =1/(1+$E$21)^J34 -> 0.78953178 | K35: =1/(1+$E$21)^K34 -> 0.70154321 | L35: =1/(1+$E$21)^L34 -> 0.62336043 | M35: =1/(1+$E$21)^M34 -> 0.55389066
B36: PV of FCFF | C36: Rs cr | I36: =I32*I35 -> 14830.938 | J36: =J32*J35 -> 14338.757 | K36: =K32*K35 -> 13922.048 | L36: =L32*L35 -> 13362.11 | M36: =M32*M35 -> 12711.846
A37: # | B37: Valuation summary
B38: Sum of PV of FCFF | C38: Rs cr | E38: =SUM(I36:M36) -> 69165.7
B39: Terminal value (Gordon growth) | C39: Rs cr | E39: =M32*(1+E22)/(E21-E22) -> 319505.95
B40: PV of terminal value | C40: Rs cr | E40: =E39*M35 -> 176971.36
B41: Enterprise value | C41: Rs cr | E41: =E38+E40 -> 246137.06
B42: Plus: cash & investments | C42: Rs cr | E42: =BS!H8 -> 38000
B43: Less: debt | C43: Rs cr | E43: =-BS!H21 -> -400
B44: Equity value | C44: Rs cr | E44: =SUM(E41:E43) -> 283737.06
B45: Shares outstanding | C45: crore | E45: =Inputs!D11 -> 1251
...

Sheet Checks
B2: Model Integrity Checks
B3: Every check must read OK. Failing checks are highlighted in red and roll up to the Cover.
A5: # | B5: Checks
B6: Check | D6: Result | E6: What it tests
B7: Balance sheet balances (all years) | D7: =IF(SUMPRODUCT(ABS(BS!H27:M27))<0.01,"OK","ERROR") -> OK | E7: Assets = liabilities + equity in every period
B8: Cash never negative | D8: =IF(MIN(BS!H8:M8)>=0,"OK","ERROR") -> OK | E8: Closing cash & investments >= 0
B9: Equity roll-forward reconciles | D9: =IF(ABS(BS!M24-BS!H24-SUM(IS!I20:M20)-SUM(CF!I20:M20))<0.01,"OK","ERROR") -> OK | E9: Closing equity = opening + net income - dividends
B10: Cash flow ties to balance sheet cash | D10: =IF(ABS(CF!M25-BS!M8)<0.01,"OK","ERROR") -> OK | E10: CF closing cash = BS cash (final year)
B11: WACC exceeds terminal growth | D11: =IF(DCF!E21>DCF!E22,"OK","ERROR") -> OK | E11: Gordon growth model is valid only when WACC > g
B12: Scenario selector valid | D12: =IF(OR(Inputs!D8=1,Inputs!D8=2,Inputs!D8=3),"OK","ERROR") -> OK | E12: Selector must be 1, 2 or 3
B13: Sensitivity table centre = DCF value | D13: =IF(ABS(DCF!F58-DCF!E46)<0.01,"OK","ERROR") -> OK | E13: Sensitivity grid reconciles to headline valuation
B14: Terminal value share of EV is reasonable | D14: =IF(DCF!E50<0.85,"OK","REVIEW") -> OK | E14: Warns if TV > 85% of enterprise value
B16: OVERALL MODEL STATUS | D16: =IF(COUNTIF(D7:D14,"OK")=8,"ALL PASS","REVIEW") -> ALL PASS
